Workbook

Sheet Milestone Tracker – IHP
A1: MILESTONE TRACKER — INDIA HERO PROJECT (IHP)
A2: Delivery / Approval / Release dates · Finance tracks Payment · Status column is automatic
A3: Sl. No | B3: Program | C3: Title | D3: Developer | E3: Milestone | F3: Description | G3: Delivery Date | H3: MS Approval Date | I3: Release Date
F75: PORTFOLIO TOTAL | H75: Paid ▶

Sheet Milestone Tracker – MENA
A1: MILESTONE TRACKER — MENA HERO PROJECT
A2: Delivery / Approval / Release dates · Finance tracks Payment · Status column is automatic
A3: Sl. No | B3: Program | C3: Title | D3: Developer | E3: Milestone | F3: Description | G3: Delivery Date | H3: MS Approval Date | I3: Release Date
A4: 1
A14: 2
A23: 3
A33: 4

Sheet Payment Engine
A1: trackRow | K1: isMS | L1: 0
A2: 4 | B2: =IF(ISBLANK(INDEX('Milestone Tracker – IHP'!$B:$B,4)),B1,INDEX('Milestone Tracker – IHP'!$B:$B,4)) -> 0 | C2: =IF(ISBLANK(INDEX('Milestone Tracker – IHP'!$C:$C,4)),C1,INDEX('Milestone Tracker – IHP'!$C:$C,4)) -> 0 | D2: =IF(ISBLANK(INDEX('Milestone Tracker – IHP'!$D:$D,4)),D1,INDEX('Milestone Tracker – IHP'!$D:$D,4)) -> 0 | E2: =IF(ISBLANK(INDEX('Milestone Tracker – IHP'!$E:$E,4)),"",INDEX('Milestone Tracker – IHP'!$E:$E,4)) | F2: =IF(ISBLANK(INDEX('Milestone Tracker – IHP'!$F:$F,4)),"",INDEX('Milestone Tracker – IHP'!$F:$F,4)) | G2: =IF(ISBLANK(INDEX('Milestone Tracker – IHP'!#REF!,4)),"",INDEX('Milestone Tracker – IHP'!#REF!,4)) -> #REF! | H2: =IF(ISBLANK(INDEX('Milestone Tracker – IHP'!$G:$G,4)),"",INDEX('Milestone Tracker – IHP'!$G:$G,4)) | I2: =IF(ISBLANK(INDEX('Milestone Tracker – IHP'!$H:$H,4)),"",INDEX('Milestone Tracker – IHP'!$H:$H,4)) | J2: =IF(ISBLANK(INDEX('Milestone Tracker – IHP'!#REF!,4)),"",INDEX('Milestone Tracker – IHP'!#REF!,4)) -> #REF! | K2: =IF(LEFT($E2,9)="Milestone",1,0) -> 0 | L2: =L1+K2 -> 0
A3: 5 | B3: =IF(ISBLANK(INDEX('Milestone Tracker – IHP'!$B:$B,5)),B2,INDEX('Milestone Tracker – IHP'!$B:$B,5)) -> 0 | C3: =IF(ISBLANK(INDEX('Milestone Tracker – IHP'!$C:$C,5)),C2,INDEX('Milestone Tracker – IHP'!$C:$C,5)) -> 0 | D3: =IF(ISBLANK(INDEX('Milestone Tracker – IHP'!$D:$D,5)),D2,INDEX('Milestone Tracker – IHP'!$D:$D,5)) -> 0 | E3: =IF(ISBLANK(INDEX('Milestone Tracker – IHP'!$E:$E,5)),"",INDEX('Milestone Tracker – IHP'!$E:$E,5)) | F3: =IF(ISBLANK(INDEX('Milestone Tracker – IHP'!$F:$F,5)),"",INDEX('Milestone Tracker – IHP'!$F:$F,5)) | G3: =IF(ISBLANK(INDEX('Milestone Tracker – IHP'!#REF!,5)),"",INDEX('Milestone Tracker – IHP'!#REF!,5)) -> #REF! | H3: =IF(ISBLANK(INDEX('Milestone Tracker – IHP'!$G:$G,5)),"",INDEX('Milestone Tracker – IHP'!$G:$G,5)) | I3: =IF(ISBLANK(INDEX('Milestone Tracker – IHP'!$H:$H,5)),"",INDEX('Milestone Tracker – IHP'!$H:$H,5)) | J3: =IF(ISBLANK(INDEX('Milestone Tracker – IHP'!#REF!,5)),"",INDEX('Milestone Tracker – IHP'!#REF!,5)) -> #REF! | K3: =IF(LEFT($E3,9)="Milestone",1,0) -> 0 | L3: =L2+K3 -> 0
A4: 6 | B4: =IF(ISBLANK(INDEX('Milestone Tracker – IHP'!$B:$B,6)),B3,INDEX('Milestone Tracker – IHP'!$B:$B,6)) -> 0 | C4: =IF(ISBLANK(INDEX('Milestone Tracker – IHP'!$C:$C,6)),C3,INDEX('Milestone Tracker – IHP'!$C:$C,6)) -> 0 | D4: =IF(ISBLANK(INDEX('Milestone Tracker – IHP'!$D:$D,6)),D3,INDEX('Milestone Tracker – IHP'!$D:$D,6)) -> 0 | E4: =IF(ISBLANK(INDEX('Milestone Tracker – IHP'!$E:$E,6)),"",INDEX('Milestone Tracker – IHP'!$E:$E,6)) | F4: =IF(ISBLANK(INDEX('Milestone Tracker – IHP'!$F:$F,6)),"",INDEX('Milestone Tracker – IHP'!$F:$F,6)) | G4: =IF(ISBLANK(INDEX('Milestone Tracker – IHP'!#REF!,6)),"",INDEX('Milestone Tracker – IHP'!#REF!,6)) -> #REF! | H4: =IF(ISBLANK(INDEX('Milestone Tracker – IHP'!$G:$G,6)),"",INDEX('Milestone Tracker – IHP'!$G:$G,6)) | I4: =IF(ISBLANK(INDEX('Milestone Tracker – IHP'!$H:$H,6)),"",INDEX('Milestone Tracker – IHP'!$H:$H,6)) | J4: =IF(ISBLANK(INDEX('Milestone Tracker – IHP'!#REF!,6)),"",INDEX('Milestone Tracker – IHP'!#REF!,6)) -> #REF! | K4: =IF(LEFT($E4,9)="Milestone",1,0) -> 0 | L4: =L3+K4 -> 0
A5: 7 | B5: =IF(ISBLANK(INDEX('Milestone Tracker – IHP'!$B:$B,7)),B4,INDEX('Milestone Tracker – IHP'!$B:$B,7)) -> 0 | C5: =IF(ISBLANK(INDEX('Milestone Tracker – IHP'!$C:$C,7)),C4,INDEX('Milestone Tracker – IHP'!$C:$C,7)) -> 0 | D5: =IF(ISBLANK(INDEX('Milestone Tracker – IHP'!$D:$D,7)),D4,INDEX('Milestone Tracker – IHP'!$D:$D,7)) -> 0 | E5: =IF(ISBLANK(INDEX('Milestone Tracker – IHP'!$E:$E,7)),"",INDEX('Milestone Tracker – IHP'!$E:$E,7)) | F5: =IF(ISBLANK(INDEX('Milestone Tracker – IHP'!$F:$F,7)),"",INDEX('Milestone Tracker – IHP'!$F:$F,7)) | G5: =IF(ISBLANK(INDEX('Milestone Tracker – IHP'!#REF!,7)),"",INDEX('Milestone Tracker – IHP'!#REF!,7)) -> #REF! | H5: =IF(ISBLANK(INDEX('Milestone Tracker – IHP'!$G:$G,7)),"",INDEX('Milestone Tracker – IHP'!$G:$G,7)) | I5: =IF(ISBLANK(INDEX('Milestone Tracker – IHP'!$H:$H,7)),"",INDEX('Milestone Tracker – IHP'!$H:$H,7)) | J5: =IF(ISBLANK(INDEX('Milestone Tracker – IHP'!#REF!,7)),"",INDEX('Milestone Tracker – IHP'!#REF!,7)) -> #REF! | K5: =IF(LEFT($E5,9)="Milestone",1,0) -> 0 | L5: =L4+K5 -> 0
A6: 8 | B6: =IF(ISBLANK(INDEX('Milestone Tracker – IHP'!$B:$B,8)),B5,INDEX('Milestone Tracker – IHP'!$B:$B,8)) -> 0 | C6: =IF(ISBLANK(INDEX('Milestone Tracker – IHP'!$C:$C,8)),C5,INDEX('Milestone Tracker – IHP'!$C:$C,8)) -> 0 | D6: =IF(ISBLANK(INDEX('Milestone Tracker – IHP'!$D:$D,8)),D5,INDEX('Milestone Tracker – IHP'!$D:$D,8)) -> 0 | E6: =IF(ISBLANK(INDEX('Milestone Tracker – IHP'!$E:$E,8)),"",INDEX('Milestone Tracker – IHP'!$E:$E,8)) | F6: =IF(ISBLANK(INDEX('Milestone Tracker – IHP'!$F:$F,8)),"",INDEX('Milestone Tracker – IHP'!$F:$F,8)) | G6: =IF(ISBLANK(INDEX('Milestone Tracker – IHP'!#REF!,8)),"",INDEX('Milestone Tracker – IHP'!#REF!,8)) -> #REF! | H6: =IF(ISBLANK(INDEX('Milestone Tracker – IHP'!$G:$G,8)),"",INDEX('Milestone Tracker – IHP'!$G:$G,8)) | I6: =IF(ISBLANK(INDEX('Milestone Tracker – IHP'!$H:$H,8)),"",INDEX('Milestone Tracker – IHP'!$H:$H,8)) | J6: =IF(ISBLANK(INDEX('Milestone Tracker – IHP'!#REF!,8)),"",INDEX('Milestone Tracker – IHP'!#REF!,8)) -> #REF! | K6: =IF(LEFT($E6,9)="Milestone",1,0) -> 0 | L6: =L5+K6 -> 0
A7: 9 | B7: =IF(ISBLANK(INDEX('Milestone Tracker – IHP'!$B:$B,9)),B6,INDEX('Milestone Tracker – IHP'!$B:$B,9)) -> 0 | C7: =IF(ISBLANK(INDEX('Milestone Tracker – IHP'!$C:$C,9)),C6,INDEX('Milestone Tracker – IHP'!$C:$C,9)) -> 0 | D7: =IF(ISBLANK(INDEX('Milestone Tracker – IHP'!$D:$D,9)),D6,INDEX('Milestone Tracker – IHP'!$D:$D,9)) -> 0 | E7: =IF(ISBLANK(INDEX('Milestone Tracker – IHP'!$E:$E,9)),"",INDEX('Milestone Tracker – IHP'!$E:$E,9)) | F7: =IF(ISBLANK(INDEX('Milestone Tracker – IHP'!$F:$F,9)),"",INDEX('Milestone Tracker – IHP'!$F:$F,9)) | G7: =IF(ISBLANK(INDEX('Milestone Tracker – IHP'!#REF!,9)),"",INDEX('Milestone Tracker – IHP'!#REF!,9)) -> #REF! | H7: =IF(ISBLANK(INDEX('Milestone Tracker – IHP'!$G:$G,9)),"",INDEX('Milestone Tracker – IHP'!$G:$G,9)) | I7: =IF(ISBLANK(INDEX('Milestone Tracker – IHP'!$H:$H,9)),"",INDEX('Milestone Tracker – IHP'!$H:$H,9)) | J7: =IF(ISBLANK(INDEX('Milestone Tracker – IHP'!#REF!,9)),"",INDEX('Milestone Tracker – IHP'!#REF!,9)) -> #REF! | K7: =IF(LEFT($E7,9)="Milestone",1,0) -> 0 | L7: =L6+K7 -> 0
A8: 10 | B8: =IF(ISBLANK(INDEX('Milestone Tracker – IHP'!$B:$B,10)),B7,INDEX('Milestone Tracker – IHP'!$B:$B,10)) -> 0 | C8: =IF(ISBLANK(INDEX('Milestone Tracker – IHP'!$C:$C,10)),C7,INDEX('Milestone Tracker – IHP'!$C:$C,10)) -> 0 | D8: =IF(ISBLANK(INDEX('Milestone Tracker – IHP'!$D:$D,10)),D7,INDEX('Milestone Tracker – IHP'!$D:$D,10)) -> 0 | E8: =IF(ISBLANK(INDEX('Milestone Tracker – IHP'!$E:$E,10)),"",INDEX('Milestone Tracker – IHP'!$E:$E,10)) | F8: =IF(ISBLANK(INDEX('Milestone Tracker – IHP'!$F:$F,10)),"",INDEX('Milestone Tracker – IHP'!$F:$F,10)) | G8: =IF(ISBLANK(INDEX('Milestone Tracker – IHP'!#REF!,10)),"",INDEX('Milestone Tracker – IHP'!#REF!,10)) -> #REF! | H8: =IF(ISBLANK(INDEX('Milestone Tracker – IHP'!$G:$G,10)),"",INDEX('Milestone Tracker – IHP'!$G:$G,10)) | I8: =IF(ISBLANK(INDEX('Milestone Tracker – IHP'!$H:$H,10)),"",INDEX('Milestone Tracker – IHP'!$H:$H,10)) | J8: =IF(ISBLANK(INDEX('Milestone Tracker – IHP'!#REF!,10)),"",INDEX('Milestone Tracker – IHP'!#REF!,10)) -> #REF! | K8: =IF(LEFT($E8,9)="Milestone",1,0) -> 0 | L8: =L7+K8 -> 0
A9: 11 | B9: =IF(ISBLANK(INDEX('Milestone Tracker – IHP'!$B:$B,11)),B8,INDEX('Milestone Tracker – IHP'!$B:$B,11)) -> 0 | C9: =IF(ISBLANK(INDEX('Milestone Tracker – IHP'!$C:$C,11)),C8,INDEX('Milestone Tracker – IHP'!$C:$C,11)) -> 0 | D9: =IF(ISBLANK(INDEX('Milestone Tracker – IHP'!$D:$D,11)),D8,INDEX('Milestone Tracker – IHP'!$D:$D,11)) -> 0 | E9: =IF(ISBLANK(INDEX('Milestone Tracker – IHP'!$E:$E,11)),"",INDEX('Milestone Tracker – IHP'!$E:$E,11)) | F9: =IF(ISBLANK(INDEX('Milestone Tracker – IHP'!$F:$F,11)),"",INDEX('Milestone Tracker – IHP'!$F:$F,11)) | G9: =IF(ISBLANK(INDEX('Milestone Tracker – IHP'!#REF!,11)),"",INDEX('Milestone Tracker – IHP'!#REF!,11)) -> #REF! | H9: =IF(ISBLANK(INDEX('Milestone Tracker – IHP'!$G:$G,11)),"",INDEX('Milestone Tracker – IHP'!$G:$G,11)) | I9: =IF(ISBLANK(INDEX('Milestone Tracker – IHP'!$H:$H,11)),"",INDEX('Milestone Tracker – IHP'!$H:$H,11)) | J9: =IF(ISBLANK(INDEX('Milestone Tracker – IHP'!#REF!,11)),"",INDEX('Milestone Tracker – IHP'!#REF!,11)) -> #REF! | K9: =IF(LEFT($E9,9)="Milestone",1,0) -> 0 | L9: =L8+K9 -> 0
A10: 12 | B10: =IF(ISBLANK(INDEX('Milestone Tracker – IHP'!$B:$B,12)),B9,INDEX('Milestone Tracker – IHP'!$B:$B,12)) -> 0 | C10: =IF(ISBLANK(INDEX('Milestone Tracker – IHP'!$C:$C,12)),C9,INDEX('Milestone Tracker – IHP'!$C:$C,12)) -> 0 | D10: =IF(ISBLANK(INDEX('Milestone Tracker – IHP'!$D:$D,12)),D9,INDEX('Milestone Tracker – IHP'!$D:$D,12)) -> 0 | E10: =IF(ISBLANK(INDEX('Milestone Tracker – IHP'!$E:$E,12)),"",INDEX('Milestone Tracker – IHP'!$E:$E,12)) | F10: =IF(ISBLANK(INDEX('Milestone Tracker – IHP'!$F:$F,12)),"",INDEX('Milestone Tracker – IHP'!$F:$F,12)) | G10: =IF(ISBLANK(INDEX('Milestone Tracker – IHP'!#REF!,12)),"",INDEX('Milestone Tracker – IHP'!#REF!,12)) -> #REF! | H10: =IF(ISBLANK(INDEX('Milestone Tracker – IHP'!$G:$G,12)),"",INDEX('Milestone Tracker – IHP'!$G:$G,12)) | I10: =IF(ISBLANK(INDEX('Milestone Tracker – IHP'!$H:$H,12)),"",INDEX('Milestone Tracker – IHP'!$H:$H,12)) | J10: =IF(ISBLANK(INDEX('Milestone Tracker – IHP'!#REF!,12)),"",INDEX('Milestone Tracker – IHP'!#REF!,12)) -> #REF! | K10: =IF(LEFT($E10,9)="Milestone",1,0) -> 0 | L10: =L9+K10 -> 0
A11: 13 | B11: =IF(ISBLANK(INDEX('Milestone Tracker – IHP'!$B:$B,13)),B10,INDEX('Milestone Tracker – IHP'!$B:$B,13)) -> 0 | C11: =IF(ISBLANK(INDEX('Milestone Tracker – IHP'!$C:$C,13)),C10,INDEX('Milestone Tracker – IHP'!$C:$C,13)) -> 0 | D11: =IF(ISBLANK(INDEX('Milestone Tracker – IHP'!$D:$D,13)),D10,INDEX('Milestone Tracker – IHP'!$D:$D,13)) -> 0 | E11: =IF(ISBLANK(INDEX('Milestone Tracker – IHP'!$E:$E,13)),"",INDEX('Milestone Tracker – IHP'!$E:$E,13)) | F11: =IF(ISBLANK(INDEX('Milestone Tracker – IHP'!$F:$F,13)),"",INDEX('Milestone Tracker – IHP'!$F:$F,13)) | G11: =IF(ISBLANK(INDEX('Milestone Tracker – IHP'!#REF!,13)),"",INDEX('Milestone Tracker – IHP'!#REF!,13)) -> #REF! | H11: =IF(ISBLANK(INDEX('Milestone Tracker – IHP'!$G:$G,13)),"",INDEX('Milestone Tracker – IHP'!$G:$G,13)) | I11: =IF(ISBLANK(INDEX('Milestone Tracker – IHP'!$H:$H,13)),"",INDEX('Milestone Tracker – IHP'!$H:$H,13)) | J11: =IF(ISBLANK(INDEX('Milestone Tracker – IHP'!#REF!,13)),"",INDEX('Milestone Tracker – IHP'!#REF!,13)) -> #REF! | K11: =IF(LEFT($E11,9)="Milestone",1,0) -> 0 | L11: =L10+K11 -> 0
A12: 14 | B12: =IF(ISBLANK(INDEX('Milestone Tracker – IHP'!$B:$B,14)),B11,INDEX('Milestone Tracker – IHP'!$B:$B,14)) -> 0 | C12: =IF(ISBLANK(INDEX('Milestone Tracker – IHP'!$C:$C,14)),C11,INDEX('Milestone Tracker – IHP'!$C:$C,14)) -> 0 | D12: =IF(ISBLANK(INDEX('Milestone Tracker – IHP'!$D:$D,14)),D11,INDEX('Milestone Tracker – IHP'!$D:$D,14)) -> 0 | E12: =IF(ISBLANK(INDEX('Milestone Tracker – IHP'!$E:$E,14)),"",INDEX('Milestone Tracker – IHP'!$E:$E,14)) | F12: =IF(ISBLANK(INDEX('Milestone Tracker – IHP'!$F:$F,14)),"",INDEX('Milestone Tracker – IHP'!$F:$F,14)) | G12: =IF(ISBLANK(INDEX('Milestone Tracker – IHP'!#REF!,14)),"",INDEX('Milestone Tracker – IHP'!#REF!,14)) -> #REF! | H12: =IF(ISBLANK(INDEX('Milestone Tracker – IHP'!$G:$G,14)),"",INDEX('Milestone Tracker – IHP'!$G:$G,14)) | I12: =IF(ISBLANK(INDEX('Milestone Tracker – IHP'!$H:$H,14)),"",INDEX('Milestone Tracker – IHP'!$H:$H,14)) | J12: =IF(ISBLANK(INDEX('Milestone Tracker – IHP'!#REF!,14)),"",INDEX('Milestone Tracker – IHP'!#REF!,14)) -> #REF! | K12: =IF(LEFT($E12,9)="Milestone",1,0) -> 0 | L12: =L11+K12 -> 0
A13: 15 | B13: =IF(ISBLANK(INDEX('Milestone Tracker – IHP'!$B:$B,15)),B12,INDEX('Milestone Tracker – IHP'!$B:$B,15)) -> 0 | C13: =IF(ISBLANK(INDEX('Milestone Tracker – IHP'!$C:$C,15)),C12,INDEX('Milestone Tracker – IHP'!$C:$C,15)) -> 0 | D13: =IF(ISBLANK(INDEX('Milestone Tracker – IHP'!$D:$D,15)),D12,INDEX('Milestone Tracker – IHP'!$D:$D,15)) -> 0 | E13: =IF(ISBLANK(INDEX('Milestone Tracker – IHP'!$E:$E,15)),"",INDEX('Milestone Tracker – IHP'!$E:$E,15)) | F13: =IF(ISBLANK(INDEX('Milestone Tracker – IHP'!$F:$F,15)),"",INDEX('Milestone Tracker – IHP'!$F:$F,15)) | G13: =IF(ISBLANK(INDEX('Milestone Tracker – IHP'!#REF!,15)),"",INDEX('Milestone Tracker – IHP'!#REF!,15)) -> #REF! | H13: =IF(ISBLANK(INDEX('Milestone Tracker – IHP'!$G:$G,15)),"",INDEX('Milestone Tracker – IHP'!$G:$G,15)) | I13: =IF(ISBLANK(INDEX('Milestone Tracker – IHP'!$H:$H,15)),"",INDEX('Milestone Tracker – IHP'!$H:$H,15)) | J13: =IF(ISBLANK(INDEX('Milestone Tracker – IHP'!#REF!,15)),"",INDEX('Milestone Tracker – IHP'!#REF!,15)) -> #REF! | K13: =IF(LEFT($E13,9)="Milestone",1,0) -> 0 | L13: =L12+K13 -> 0
A14: 16 | B14: =IF(ISBLANK(INDEX('Milestone Tracker – IHP'!$B:$B,16)),B13,INDEX('Milestone Tracker – IHP'!$B:$B,16)) -> 0 | C14: =IF(ISBLANK(INDEX('Milestone Tracker – IHP'!$C:$C,16)),C13,INDEX('Milestone Tracker – IHP'!$C:$C,16)) -> 0 | D14: =IF(ISBLANK(INDEX('Milestone Tracker – IHP'!$D:$D,16)),D13,INDEX('Milestone Tracker – IHP'!$D:$D,16)) -> 0 | E14: =IF(ISBLANK(INDEX('Milestone Tracker – IHP'!$E:$E,16)),"",INDEX('Milestone Tracker – IHP'!$E:$E,16)) | F14: =IF(ISBLANK(INDEX('Milestone Tracker – IHP'!$F:$F,16)),"",INDEX('Milestone Tracker – IHP'!$F:$F,16)) | G14: =IF(ISBLANK(INDEX('Milestone Tracker – IHP'!#REF!,16)),"",INDEX('Milestone Tracker – IHP'!#REF!,16)) -> #REF! | H14: =IF(ISBLANK(INDEX('Milestone Tracker – IHP'!$G:$G,16)),"",INDEX('Milestone Tracker – IHP'!$G:$G,16)) | I14: =IF(ISBLANK(INDEX('Milestone Tracker – IHP'!$H:$H,16)),"",INDEX('Milestone Tracker – IHP'!$H:$H,16)) | J14: =IF(ISBLANK(INDEX('Milestone Tracker – IHP'!#REF!,16)),"",INDEX('Milestone Tracker – IHP'!#REF!,16)) -> #REF! | K14: =IF(LEFT($E14,9)="Milestone",1,0) -> 0 | L14: =L13+K14 -> 0
A15: 17 | B15: =IF(ISBLANK(INDEX('Milestone Tracker – IHP'!$B:$B,17)),B14,INDEX('Milestone Tracker – IHP'!$B:$B,17)) -> 0 | C15: =IF(ISBLANK(INDEX('Milestone Tracker – IHP'!$C:$C,17)),C14,INDEX('Milestone Tracker – IHP'!$C:$C,17)) -> 0 | D15: =IF(ISBLANK(INDEX('Milestone Tracker – IHP'!$D:$D,17)),D14,INDEX('Milestone Tracker – IHP'!$D:$D,17)) -> 0 | E15: =IF(ISBLANK(INDEX('Milestone Tracker – IHP'!$E:$E,17)),"",INDEX('Milestone Tracker – IHP'!$E:$E,17)) | F15: =IF(ISBLANK(INDEX('Milestone Tracker – IHP'!$F:$F,17)),"",INDEX('Milestone Tracker – IHP'!$F:$F,17)) | G15: =IF(ISBLANK(INDEX('Milestone Tracker – IHP'!#REF!,17)),"",INDEX('Milestone Tracker – IHP'!#REF!,17)) -> #REF! | H15: =IF(ISBLANK(INDEX('Milestone Tracker – IHP'!$G:$G,17)),"",INDEX('Milestone Tracker – IHP'!$G:$G,17)) | I15: =IF(ISBLANK(INDEX('Milestone Tracker – IHP'!$H:$H,17)),"",INDEX('Milestone Tracker – IHP'!$H:$H,17)) | J15: =IF(ISBLANK(INDEX('Milestone Tracker – IHP'!#REF!,17)),"",INDEX('Milestone Tracker – IHP'!#REF!,17)) -> #REF! | K15: =IF(LEFT($E15,9)="Milestone",1,0) -> 0 | L15: =L14+K15 -> 0
A16: 18 | B16: =IF(ISBLANK(INDEX('Milestone Tracker – IHP'!$B:$B,18)),B15,INDEX('Milestone Tracker – IHP'!$B:$B,18)) -> 0 | C16: =IF(ISBLANK(INDEX('Milestone Tracker – IHP'!$C:$C,18)),C15,INDEX('Milestone Tracker – IHP'!$C:$C,18)) -> 0 | D16: =IF(ISBLANK(INDEX('Milestone Tracker – IHP'!$D:$D,18)),D15,INDEX('Milestone Tracker – IHP'!$D:$D,18)) -> 0 | E16: =IF(ISBLANK(INDEX('Milestone Tracker – IHP'!$E:$E,18)),"",INDEX('Milestone Tracker – IHP'!$E:$E,18)) | F16: =IF(ISBLANK(INDEX('Milestone Tracker – IHP'!$F:$F,18)),"",INDEX('Milestone Tracker – IHP'!$F:$F,18)) | G16: =IF(ISBLANK(INDEX('Milestone Tracker – IHP'!#REF!,18)),"",INDEX('Milestone Tracker – IHP'!#REF!,18)) -> #REF! | H16: =IF(ISBLANK(INDEX('Milestone Tracker – IHP'!$G:$G,18)),"",INDEX('Milestone Tracker – IHP'!$G:$G,18)) | I16: =IF(ISBLANK(INDEX('Milestone Tracker – IHP'!$H:$H,18)),"",INDEX('Milestone Tracker – IHP'!$H:$H,18)) | J16: =IF(ISBLANK(INDEX('Milestone Tracker – IHP'!#REF!,18)),"",INDEX('Milestone Tracker – IHP'!#REF!,18)) -> #REF! | K16: =IF(LEFT($E16,9)="Milestone",1,0) -> 0 | L16: =L15+K16 -> 0
A17: 19 | B17: =IF(ISBLANK(INDEX('Milestone Tracker – IHP'!$B:$B,19)),B16,INDEX('Milestone Tracker – IHP'!$B:$B,19)) -> 0 | C17: =IF(ISBLANK(INDEX('Milestone Tracker – IHP'!$C:$C,19)),C16,INDEX('Milestone Tracker – IHP'!$C:$C,19)) -> 0 | D17: =IF(ISBLANK(INDEX('Milestone Tracker – IHP'!$D:$D,19)),D16,INDEX('Milestone Tracker – IHP'!$D:$D,19)) -> 0 | E17: =IF(ISBLANK(INDEX('Milestone Tracker – IHP'!$E:$E,19)),"",INDEX('Milestone Tracker – IHP'!$E:$E,19)) | F17: =IF(ISBLANK(INDEX('Milestone Tracker – IHP'!$F:$F,19)),"",INDEX('Milestone Tracker – IHP'!$F:$F,19)) | G17: =IF(ISBLANK(INDEX('Milestone Tracker – IHP'!#REF!,19)),"",INDEX('Milestone Tracker – IHP'!#REF!,19)) -> #REF! | H17: =IF(ISBLANK(INDEX('Milestone Tracker – IHP'!$G:$G,19)),"",INDEX('Milestone Tracker – IHP'!$G:$G,19)) | I17: =IF(ISBLANK(INDEX('Milestone Tracker – IHP'!$H:$H,19)),"",INDEX('Milestone Tracker – IHP'!$H:$H,19)) | J17: =IF(ISBLANK(INDEX('Milestone Tracker – IHP'!#REF!,19)),"",INDEX('Milestone Tracker – IHP'!#REF!,19)) -> #REF! | K17: =IF(LEFT($E17,9)="Milestone",1,0) -> 0 | L17: =L16+K17 -> 0
A18: 20 | B18: =IF(ISBLANK(INDEX('Milestone Tracker – IHP'!$B:$B,20)),B17,INDEX('Milestone Tracker – IHP'!$B:$B,20)) -> 0 | C18: =IF(ISBLANK(INDEX('Milestone Tracker – IHP'!$C:$C,20)),C17,INDEX('Milestone Tracker – IHP'!$C:$C,20)) -> 0 | D18: =IF(ISBLANK(INDEX('Milestone Tracker – IHP'!$D:$D,20)),D17,INDEX('Milestone Tracker – IHP'!$D:$D,20)) -> 0 | E18: =IF(ISBLANK(INDEX('Milestone Tracker – IHP'!$E:$E,20)),"",INDEX('Milestone Tracker – IHP'!$E:$E,20)) | F18: =IF(ISBLANK(INDEX('Milestone Tracker – IHP'!$F:$F,20)),"",INDEX('Milestone Tracker – IHP'!$F:$F,20)) | G18: =IF(ISBLANK(INDEX('Milestone Tracker – IHP'!#REF!,20)),"",INDEX('Milestone Tracker – IHP'!#REF!,20)) -> #REF! | H18: =IF(ISBLANK(INDEX('Milestone Tracker – IHP'!$G:$G,20)),"",INDEX('Milestone Tracker – IHP'!$G:$G,20)) | I18: =IF(ISBLANK(INDEX('Milestone Tracker – IHP'!$H:$H,20)),"",INDEX('Milestone Tracker – IHP'!$H:$H,20)) | J18: =IF(ISBLANK(INDEX('Milestone Tracker – IHP'!#REF!,20)),"",INDEX('Milestone Tracker – IHP'!#REF!,20)) -> #REF! | K18: =IF(LEFT($E18,9)="Milestone",1,0) -> 0 | L18: =L17+K18 -> 0
A19: 21 | B19: =IF(ISBLANK(INDEX('Milestone Tracker – IHP'!$B:$B,21)),B18,INDEX('Milestone Tracker – IHP'!$B:$B,21)) -> 0 | C19: =IF(ISBLANK(INDEX('Milestone Tracker – IHP'!$C:$C,21)),C18,INDEX('Milestone Tracker – IHP'!$C:$C,21)) -> 0 | D19: =IF(ISBLANK(INDEX('Milestone Tracker – IHP'!$D:$D,21)),D18,INDEX('Milestone Tracker – IHP'!$D:$D,21)) -> 0 | E19: =IF(ISBLANK(INDEX('Milestone Tracker – IHP'!$E:$E,21)),"",INDEX('Milestone Tracker – IHP'!$E:$E,21)) | F19: =IF(ISBLANK(INDEX('Milestone Tracker – IHP'!$F:$F,21)),"",INDEX('Milestone Tracker – IHP'!$F:$F,21)) | G19: =IF(ISBLANK(INDEX('Milestone Tracker – IHP'!#REF!,21)),"",INDEX('Milestone Tracker – IHP'!#REF!,21)) -> #REF! | H19: =IF(ISBLANK(INDEX('Milestone Tracker – IHP'!$G:$G,21)),"",INDEX('Milestone Tracker – IHP'!$G:$G,21)) | I19: =IF(ISBLANK(INDEX('Milestone Tracker – IHP'!$H:$H,21)),"",INDEX('Milestone Tracker – IHP'!$H:$H,21)) | J19: =IF(ISBLANK(INDEX('Milestone Tracker – IHP'!#REF!,21)),"",INDEX('Milestone Tracker – IHP'!#REF!,21)) -> #REF! | K19: =IF(LEFT($E19,9)="Milestone",1,0) -> 0 | L19: =L18+K19 -> 0
A20: 22 | B20: =IF(ISBLANK(INDEX('Milestone Tracker – IHP'!$B:$B,22)),B19,INDEX('Milestone Tracker – IHP'!$B:$B,22)) -> 0 | C20: =IF(ISBLANK(INDEX('Milestone Tracker – IHP'!$C:$C,22)),C19,INDEX('Milestone Tracker – IHP'!$C:$C,22)) -> 0 | D20: =IF(ISBLANK(INDEX('Milestone Tracker – IHP'!$D:$D,22)),D19,INDEX('Milestone Tracker – IHP'!$D:$D,22)) -> 0 | E20: =IF(ISBLANK(INDEX('Milestone Tracker – IHP'!$E:$E,22)),"",INDEX('Milestone Tracker – IHP'!$E:$E,22)) | F20: =IF(ISBLANK(INDEX('Milestone Tracker – IHP'!$F:$F,22)),"",INDEX('Milestone Tracker – IHP'!$F:$F,22)) | G20: =IF(ISBLANK(INDEX('Milestone Tracker – IHP'!#REF!,22)),"",INDEX('Milestone Tracker – IHP'!#REF!,22)) -> #REF! | H20: =IF(ISBLANK(INDEX('Milestone Tracker – IHP'!$G:$G,22)),"",INDEX('Milestone Tracker – IHP'!$G:$G,22)) | I20: =IF(ISBLANK(INDEX('Milestone Tracker – IHP'!$H:$H,22)),"",INDEX('Milestone Tracker – IHP'!$H:$H,22)) | J20: =IF(ISBLANK(INDEX('Milestone Tracker – IHP'!#REF!,22)),"",INDEX('Milestone Tracker – IHP'!#REF!,22)) -> #REF! | K20: =IF(LEFT($E20,9)="Milestone",1,0) -> 0 | L20: =L19+K20 -> 0
A21: 23 | B21: =IF(ISBLANK(INDEX('Milestone Tracker – IHP'!$B:$B,23)),B20,INDEX('Milestone Tracker – IHP'!$B:$B,23)) -> 0 | C21: =IF(ISBLANK(INDEX('Milestone Tracker – IHP'!$C:$C,23)),C20,INDEX('Milestone Tracker – IHP'!$C:$C,23)) -> 0 | D21: =IF(ISBLANK(INDEX('Milestone Tracker – IHP'!$D:$D,23)),D20,INDEX('Milestone Tracker – IHP'!$D:$D,23)) -> 0 | E21: =IF(ISBLANK(INDEX('Milestone Tracker – IHP'!$E:$E,23)),"",INDEX('Milestone Tracker – IHP'!$E:$E,23)) | F21: =IF(ISBLANK(INDEX('Milestone Tracker – IHP'!$F:$F,23)),"",INDEX('Milestone Tracker – IHP'!$F:$F,23)) | G21: =IF(ISBLANK(INDEX('Milestone Tracker – IHP'!#REF!,23)),"",INDEX('Milestone Tracker – IHP'!#REF!,23)) -> #REF! | H21: =IF(ISBLANK(INDEX('Milestone Tracker – IHP'!$G:$G,23)),"",INDEX('Milestone Tracker – IHP'!$G:$G,23)) | I21: =IF(ISBLANK(INDEX('Milestone Tracker – IHP'!$H:$H,23)),"",INDEX('Milestone Tracker – IHP'!$H:$H,23)) | J21: =IF(ISBLANK(INDEX('Milestone Tracker – IHP'!#REF!,23)),"",INDEX('Milestone Tracker – IHP'!#REF!,23)) -> #REF! | K21: =IF(LEFT($E21,9)="Milestone",1,0) -> 0 | L21: =L20+K21 -> 0
A22: 24 | B22: =IF(ISBLANK(INDEX('Milestone Tracker – IHP'!$B:$B,24)),B21,INDEX('Milestone Tracker – IHP'!$B:$B,24)) -> 0 | C22: =IF(ISBLANK(INDEX('Milestone Tracker – IHP'!$C:$C,24)),C21,INDEX('Milestone Tracker – IHP'!$C:$C,24)) -> 0 | D22: =IF(ISBLANK(INDEX('Milestone Tracker – IHP'!$D:$D,24)),D21,INDEX('Milestone Tracker – IHP'!$D:$D,24)) -> 0 | E22: =IF(ISBLANK(INDEX('Milestone Tracker – IHP'!$E:$E,24)),"",INDEX('Milestone Tracker – IHP'!$E:$E,24)) | F22: =IF(ISBLANK(INDEX('Milestone Tracker – IHP'!$F:$F,24)),"",INDEX('Milestone Tracker – IHP'!$F:$F,24)) | G22: =IF(ISBLANK(INDEX('Milestone Tracker – IHP'!#REF!,24)),"",INDEX('Milestone Tracker – IHP'!#REF!,24)) -> #REF! | H22: =IF(ISBLANK(INDEX('Milestone Tracker – IHP'!$G:$G,24)),"",INDEX('Milestone Tracker – IHP'!$G:$G,24)) | I22: =IF(ISBLANK(INDEX('Milestone Tracker – IHP'!$H:$H,24)),"",INDEX('Milestone Tracker – IHP'!$H:$H,24)) | J22: =IF(ISBLANK(INDEX('Milestone Tracker – IHP'!#REF!,24)),"",INDEX('Milestone Tracker – IHP'!#REF!,24)) -> #REF! | K22: =IF(LEFT($E22,9)="Milestone",1,0) -> 0 | L22: =L21+K22 -> 0
A23: 25 | B23: =IF(ISBLANK(INDEX('Milestone Tracker – IHP'!$B:$B,25)),B22,INDEX('Milestone Tracker – IHP'!$B:$B,25)) -> 0 | C23: =IF(ISBLANK(INDEX('Milestone Tracker – IHP'!$C:$C,25)),C22,INDEX('Milestone Tracker – IHP'!$C:$C,25)) -> 0 | D23: =IF(ISBLANK(INDEX('Milestone Tracker – IHP'!$D:$D,25)),D22,INDEX('Milestone Tracker – IHP'!$D:$D,25)) -> 0 | E23: =IF(ISBLANK(INDEX('Milestone Tracker – IHP'!$E:$E,25)),"",INDEX('Milestone Tracker – IHP'!$E:$E,25)) | F23: =IF(ISBLANK(INDEX('Milestone Tracker – IHP'!$F:$F,25)),"",INDEX('Milestone Tracker – IHP'!$F:$F,25)) | G23: =IF(ISBLANK(INDEX('Milestone Tracker – IHP'!#REF!,25)),"",INDEX('Milestone Tracker – IHP'!#REF!,25)) -> #REF! | H23: =IF(ISBLANK(INDEX('Milestone Tracker – IHP'!$G:$G,25)),"",INDEX('Milestone Tracker – IHP'!$G:$G,25)) | I23: =IF(ISBLANK(INDEX('Milestone Tracker – IHP'!$H:$H,25)),"",INDEX('Milestone Tracker – IHP'!$H:$H,25)) | J23: =IF(ISBLANK(INDEX('Milestone Tracker – IHP'!#REF!,25)),"",INDEX('Milestone Tracker – IHP'!#REF!,25)) -> #REF! | K23: =IF(LEFT($E23,9)="Milestone",1,0) -> 0 | L23: =L22+K23 -> 0
A24: 26 | B24: =IF(ISBLANK(INDEX('Milestone Tracker – IHP'!$B:$B,26)),B23,INDEX('Milestone Tracker – IHP'!$B:$B,26)) -> 0 | C24: =IF(ISBLANK(INDEX('Milestone Tracker – IHP'!$C:$C,26)),C23,INDEX('Milestone Tracker – IHP'!$C:$C,26)) -> 0 | D24: =IF(ISBLANK(INDEX('Milestone Tracker – IHP'!$D:$D,26)),D23,INDEX('Milestone Tracker – IHP'!$D:$D,26)) -> 0 | E24: =IF(ISBLANK(INDEX('Milestone Tracker – IHP'!$E:$E,26)),"",INDEX('Milestone Tracker – IHP'!$E:$E,26)) | F24: =IF(ISBLANK(INDEX('Milestone Tracker – IHP'!$F:$F,26)),"",INDEX('Milestone Tracker – IHP'!$F:$F,26)) | G24: =IF(ISBLANK(INDEX('Milestone Tracker – IHP'!#REF!,26)),"",INDEX('Milestone Tracker – IHP'!#REF!,26)) -> #REF! | H24: =IF(ISBLANK(INDEX('Milestone Tracker – IHP'!$G:$G,26)),"",INDEX('Milestone Tracker – IHP'!$G:$G,26)) | I24: =IF(ISBLANK(INDEX('Milestone Tracker – IHP'!$H:$H,26)),"",INDEX('Milestone Tracker – IHP'!$H:$H,26)) | J24: =IF(ISBLANK(INDEX('Milestone Tracker – IHP'!#REF!,26)),"",INDEX('Milestone Tracker – IHP'!#REF!,26)) -> #REF! | K24: =IF(LEFT($E24,9)="Milestone",1,0) -> 0 | L24: =L23+K24 -> 0
A25: 27 | B25: =IF(ISBLANK(INDEX('Milestone Tracker – IHP'!$B:$B,27)),B24,INDEX('Milestone Tracker – IHP'!$B:$B,27)) -> 0 | C25: =IF(ISBLANK(INDEX('Milestone Tracker – IHP'!$C:$C,27)),C24,INDEX('Milestone Tracker – IHP'!$C:$C,27)) -> 0 | D25: =IF(ISBLANK(INDEX('Milestone Tracker – IHP'!$D:$D,27)),D24,INDEX('Milestone Tracker – IHP'!$D:$D,27)) -> 0 | E25: =IF(ISBLANK(INDEX('Milestone Tracker – IHP'!$E:$E,27)),"",INDEX('Milestone Tracker – IHP'!$E:$E,27)) | F25: =IF(ISBLANK(INDEX('Milestone Tracker – IHP'!$F:$F,27)),"",INDEX('Milestone Tracker – IHP'!$F:$F,27)) | G25: =IF(ISBLANK(INDEX('Milestone Tracker – IHP'!#REF!,27)),"",INDEX('Milestone Tracker – IHP'!#REF!,27)) -> #REF! | H25: =IF(ISBLANK(INDEX('Milestone Tracker – IHP'!$G:$G,27)),"",INDEX('Milestone Tracker – IHP'!$G:$G,27)) | I25: =IF(ISBLANK(INDEX('Milestone Tracker – IHP'!$H:$H,27)),"",INDEX('Milestone Tracker – IHP'!$H:$H,27)) | J25: =IF(ISBLANK(INDEX('Milestone Tracker – IHP'!#REF!,27)),"",INDEX('Milestone Tracker – IHP'!#REF!,27)) -> #REF! | K25: =IF(LEFT($E25,9)="Milestone",1,0) -> 0 | L25: =L24+K25 -> 0
A26: 28 | B26: =IF(ISBLANK(INDEX('Milestone Tracker – IHP'!$B:$B,28)),B25,INDEX('Milestone Tracker – IHP'!$B:$B,28)) -> 0 | C26: =IF(ISBLANK(INDEX('Milestone Tracker – IHP'!$C:$C,28)),C25,INDEX('Milestone Tracker – IHP'!$C:$C,28)) -> 0 | D26: =IF(ISBLANK(INDEX('Milestone Tracker – IHP'!$D:$D,28)),D25,INDEX('Milestone Tracker – IHP'!$D:$D,28)) -> 0 | E26: =IF(ISBLANK(INDEX('Milestone Tracker – IHP'!$E:$E,28)),"",INDEX('Milestone Tracker – IHP'!$E:$E,28)) | F26: =IF(ISBLANK(INDEX('Milestone Tracker – IHP'!$F:$F,28)),"",INDEX('Milestone Tracker – IHP'!$F:$F,28)) | G26: =IF(ISBLANK(INDEX('Milestone Tracker – IHP'!#REF!,28)),"",INDEX('Milestone Tracker – IHP'!#REF!,28)) -> #REF! | H26: =IF(ISBLANK(INDEX('Milestone Tracker – IHP'!$G:$G,28)),"",INDEX('Milestone Tracker – IHP'!$G:$G,28)) | I26: =IF(ISBLANK(INDEX('Milestone Tracker – IHP'!$H:$H,28)),"",INDEX('Milestone Tracker – IHP'!$H:$H,28)) | J26: =IF(ISBLANK(INDEX('Milestone Tracker – IHP'!#REF!,28)),"",INDEX('Milestone Tracker – IHP'!#REF!,28)) -> #REF! | K26: =IF(LEFT($E26,9)="Milestone",1,0) -> 0 | L26: =L25+K26 -> 0
A27: 29 | B27: =IF(ISBLANK(INDEX('Milestone Tracker – IHP'!$B:$B,29)),B26,INDEX('Milestone Tracker – IHP'!$B:$B,29)) -> 0 | C27: =IF(ISBLANK(INDEX('Milestone Tracker – IHP'!$C:$C,29)),C26,INDEX('Milestone Tracker – IHP'!$C:$C,29)) -> 0 | D27: =IF(ISBLANK(INDEX('Milestone Tracker – IHP'!$D:$D,29)),D26,INDEX('Milestone Tracker – IHP'!$D:$D,29)) -> 0 | E27: =IF(ISBLANK(INDEX('Milestone Tracker – IHP'!$E:$E,29)),"",INDEX('Milestone Tracker – IHP'!$E:$E,29)) | F27: =IF(ISBLANK(INDEX('Milestone Tracker – IHP'!$F:$F,29)),"",INDEX('Milestone Tracker – IHP'!$F:$F,29)) | G27: =IF(ISBLANK(INDEX('Milestone Tracker – IHP'!#REF!,29)),"",INDEX('Milestone Tracker – IHP'!#REF!,29)) -> #REF! | H27: =IF(ISBLANK(INDEX('Milestone Tracker – IHP'!$G:$G,29)),"",INDEX('Milestone Tracker – IHP'!$G:$G,29)) | I27: =IF(ISBLANK(INDEX('Milestone Tracker – IHP'!$H:$H,29)),"",INDEX('Milestone Tracker – IHP'!$H:$H,29)) | J27: =IF(ISBLANK(INDEX('Milestone Tracker – IHP'!#REF!,29)),"",INDEX('Milestone Tracker – IHP'!#REF!,29)) -> #REF! | K27: =IF(LEFT($E27,9)="Milestone",1,0) -> 0 | L27: =L26+K27 -> 0
A28: 30 | B28: =IF(ISBLANK(INDEX('Milestone Tracker – IHP'!$B:$B,30)),B27,INDEX('Milestone Tracker – IHP'!$B:$B,30)) -> 0 | C28: =IF(ISBLANK(INDEX('Milestone Tracker – IHP'!$C:$C,30)),C27,INDEX('Milestone Tracker – IHP'!$C:$C,30)) -> 0 | D28: =IF(ISBLANK(INDEX('Milestone Tracker – IHP'!$D:$D,30)),D27,INDEX('Milestone Tracker – IHP'!$D:$D,30)) -> 0 | E28: =IF(ISBLANK(INDEX('Milestone Tracker – IHP'!$E:$E,30)),"",INDEX('Milestone Tracker – IHP'!$E:$E,30)) | F28: =IF(ISBLANK(INDEX('Milestone Tracker – IHP'!$F:$F,30)),"",INDEX('Milestone Tracker – IHP'!$F:$F,30)) | G28: =IF(ISBLANK(INDEX('Milestone Tracker – IHP'!#REF!,30)),"",INDEX('Milestone Tracker – IHP'!#REF!,30)) -> #REF! | H28: =IF(ISBLANK(INDEX('Milestone Tracker – IHP'!$G:$G,30)),"",INDEX('Milestone Tracker – IHP'!$G:$G,30)) | I28: =IF(ISBLANK(INDEX('Milestone Tracker – IHP'!$H:$H,30)),"",INDEX('Milestone Tracker – IHP'!$H:$H,30)) | J28: =IF(ISBLANK(INDEX('Milestone Tracker – IHP'!#REF!,30)),"",INDEX('Milestone Tracker – IHP'!#REF!,30)) -> #REF! | K28: =IF(LEFT($E28,9)="Milestone",1,0) -> 0 | L28: =L27+K28 -> 0
A29: 31 | B29: =IF(ISBLANK(INDEX('Milestone Tracker – IHP'!$B:$B,31)),B28,INDEX('Milestone Tracker – IHP'!$B:$B,31)) -> 0 | C29: =IF(ISBLANK(INDEX('Milestone Tracker – IHP'!$C:$C,31)),C28,INDEX('Milestone Tracker – IHP'!$C:$C,31)) -> 0 | D29: =IF(ISBLANK(INDEX('Milestone Tracker – IHP'!$D:$D,31)),D28,INDEX('Milestone Tracker – IHP'!$D:$D,31)) -> 0 | E29: =IF(ISBLANK(INDEX('Milestone Tracker – IHP'!$E:$E,31)),"",INDEX('Milestone Tracker – IHP'!$E:$E,31)) | F29: =IF(ISBLANK(INDEX('Milestone Tracker – IHP'!$F:$F,31)),"",INDEX('Milestone Tracker – IHP'!$F:$F,31)) | G29: =IF(ISBLANK(INDEX('Milestone Tracker – IHP'!#REF!,31)),"",INDEX('Milestone Tracker – IHP'!#REF!,31)) -> #REF! | H29: =IF(ISBLANK(INDEX('Milestone Tracker – IHP'!$G:$G,31)),"",INDEX('Milestone Tracker – IHP'!$G:$G,31)) | I29: =IF(ISBLANK(INDEX('Milestone Tracker – IHP'!$H:$H,31)),"",INDEX('Milestone Tracker – IHP'!$H:$H,31)) | J29: =IF(ISBLANK(INDEX('Milestone Tracker – IHP'!#REF!,31)),"",INDEX('Milestone Tracker – IHP'!#REF!,31)) -> #REF! | K29: =IF(LEFT($E29,9)="Milestone",1,0) -> 0 | L29: =L28+K29 -> 0
A30: 32 | B30: =IF(ISBLANK(INDEX('Milestone Tracker – IHP'!$B:$B,32)),B29,INDEX('Milestone Tracker – IHP'!$B:$B,32)) -> 0 | C30: =IF(ISBLANK(INDEX('Milestone Tracker – IHP'!$C:$C,32)),C29,INDEX('Milestone Tracker – IHP'!$C:$C,32)) -> 0 | D30: =IF(ISBLANK(INDEX('Milestone Tracker – IHP'!$D:$D,32)),D29,INDEX('Milestone Tracker – IHP'!$D:$D,32)) -> 0 | E30: =IF(ISBLANK(INDEX('Milestone Tracker – IHP'!$E:$E,32)),"",INDEX('Milestone Tracker – IHP'!$E:$E,32)) | F30: =IF(ISBLANK(INDEX('Milestone Tracker – IHP'!$F:$F,32)),"",INDEX('Milestone Tracker – IHP'!$F:$F,32)) | G30: =IF(ISBLANK(INDEX('Milestone Tracker – IHP'!#REF!,32)),"",INDEX('Milestone Tracker – IHP'!#REF!,32)) -> #REF! | H30: =IF(ISBLANK(INDEX('Milestone Tracker – IHP'!$G:$G,32)),"",INDEX('Milestone Tracker – IHP'!$G:$G,32)) | I30: =IF(ISBLANK(INDEX('Milestone Tracker – IHP'!$H:$H,32)),"",INDEX('Milestone Tracker – IHP'!$H:$H,32)) | J30: =IF(ISBLANK(INDEX('Milestone Tracker – IHP'!#REF!,32)),"",INDEX('Milestone Tracker – IHP'!#REF!,32)) -> #REF! | K30: =IF(LEFT($E30,9)="Milestone",1,0) -> 0 | L30: =L29+K30 -> 0
A31: 33 | B31: =IF(ISBLANK(INDEX('Milestone Tracker – IHP'!$B:$B,33)),B30,INDEX('Milestone Tracker – IHP'!$B:$B,33)) -> 0 | C31: =IF(ISBLANK(INDEX('Milestone Tracker – IHP'!$C:$C,33)),C30,INDEX('Milestone Tracker – IHP'!$C:$C,33)) -> 0 | D31: =IF(ISBLANK(INDEX('Milestone Tracker – IHP'!$D:$D,33)),D30,INDEX('Milestone Tracker – IHP'!$D:$D,33)) -> 0 | E31: =IF(ISBLANK(INDEX('Milestone Tracker – IHP'!$E:$E,33)),"",INDEX('Milestone Tracker – IHP'!$E:$E,33)) | F31: =IF(ISBLANK(INDEX('Milestone Tracker – IHP'!$F:$F,33)),"",INDEX('Milestone Tracker – IHP'!$F:$F,33)) | G31: =IF(ISBLANK(INDEX('Milestone Tracker – IHP'!#REF!,33)),"",INDEX('Milestone Tracker – IHP'!#REF!,33)) -> #REF! | H31: =IF(ISBLANK(INDEX('Milestone Tracker – IHP'!$G:$G,33)),"",INDEX('Milestone Tracker – IHP'!$G:$G,33)) | I31: =IF(ISBLANK(INDEX('Milestone Tracker – IHP'!$H:$H,33)),"",INDEX('Milestone Tracker – IHP'!$H:$H,33)) | J31: =IF(ISBLANK(INDEX('Milestone Tracker – IHP'!#REF!,33)),"",INDEX('Milestone Tracker – IHP'!#REF!,33)) -> #REF! | K31: =IF(LEFT($E31,9)="Milestone",1,0) -> 0 | L31: =L30+K31 -> 0
A32: 34 | B32: =IF(ISBLANK(INDEX('Milestone Tracker – IHP'!$B:$B,34)),B31,INDEX('Milestone Tracker – IHP'!$B:$B,34)) -> 0 | C32: =IF(ISBLANK(INDEX('Milestone Tracker – IHP'!$C:$C,34)),C31,INDEX('Milestone Tracker – IHP'!$C:$C,34)) -> 0 | D32: =IF(ISBLANK(INDEX('Milestone Tracker – IHP'!$D:$D,34)),D31,INDEX('Milestone Tracker – IHP'!$D:$D,34)) -> 0 | E32: =IF(ISBLANK(INDEX('Milestone Tracker – IHP'!$E:$E,34)),"",INDEX('Milestone Tracker – IHP'!$E:$E,34)) | F32: =IF(ISBLANK(INDEX('Milestone Tracker – IHP'!$F:$F,34)),"",INDEX('Milestone Tracker – IHP'!$F:$F,34)) | G32: =IF(ISBLANK(INDEX('Milestone Tracker – IHP'!#REF!,34)),"",INDEX('Milestone Tracker – IHP'!#REF!,34)) -> #REF! | H32: =IF(ISBLANK(INDEX('Milestone Tracker – IHP'!$G:$G,34)),"",INDEX('Milestone Tracker – IHP'!$G:$G,34)) | I32: =IF(ISBLANK(INDEX('Milestone Tracker – IHP'!$H:$H,34)),"",INDEX('Milestone Tracker – IHP'!$H:$H,34)) | J32: =IF(ISBLANK(INDEX('Milestone Tracker – IHP'!#REF!,34)),"",INDEX('Milestone Tracker – IHP'!#REF!,34)) -> #REF! | K32: =IF(LEFT($E32,9)="Milestone",1,0) -> 0 | L32: =L31+K32 -> 0
A33: 35 | B33: =IF(ISBLANK(INDEX('Milestone Tracker – IHP'!$B:$B,35)),B32,INDEX('Milestone Tracker – IHP'!$B:$B,35)) -> 0 | C33: =IF(ISBLANK(INDEX('Milestone Tracker – IHP'!$C:$C,35)),C32,INDEX('Milestone Tracker – IHP'!$C:$C,35)) -> 0 | D33: =IF(ISBLANK(INDEX('Milestone Tracker – IHP'!$D:$D,35)),D32,INDEX('Milestone Tracker – IHP'!$D:$D,35)) -> 0 | E33: =IF(ISBLANK(INDEX('Milestone Tracker – IHP'!$E:$E,35)),"",INDEX('Milestone Tracker – IHP'!$E:$E,35)) | F33: =IF(ISBLANK(INDEX('Milestone Tracker – IHP'!$F:$F,35)),"",INDEX('Milestone Tracker – IHP'!$F:$F,35)) | G33: =IF(ISBLANK(INDEX('Milestone Tracker – IHP'!#REF!,35)),"",INDEX('Milestone Tracker – IHP'!#REF!,35)) -> #REF! | H33: =IF(ISBLANK(INDEX('Milestone Tracker – IHP'!$G:$G,35)),"",INDEX('Milestone Tracker – IHP'!$G:$G,35)) | I33: =IF(ISBLANK(INDEX('Milestone Tracker – IHP'!$H:$H,35)),"",INDEX('Milestone Tracker – IHP'!$H:$H,35)) | J33: =IF(ISBLANK(INDEX('Milestone Tracker – IHP'!#REF!,35)),"",INDEX('Milestone Tracker – IHP'!#REF!,35)) -> #REF! | K33: =IF(LEFT($E33,9)="Milestone",1,0) -> 0 | L33: =L32+K33 -> 0
A34: 36 | B34: =IF(ISBLANK(INDEX('Milestone Tracker – IHP'!$B:$B,36)),B33,INDEX('Milestone Tracker – IHP'!$B:$B,36)) -> 0 | C34: =IF(ISBLANK(INDEX('Milestone Tracker – IHP'!$C:$C,36)),C33,INDEX('Milestone Tracker – IHP'!$C:$C,36)) -> 0 | D34: =IF(ISBLANK(INDEX('Milestone Tracker – IHP'!$D:$D,36)),D33,INDEX('Milestone Tracker – IHP'!$D:$D,36)) -> 0 | E34: =IF(ISBLANK(INDEX('Milestone Tracker – IHP'!$E:$E,36)),"",INDEX('Milestone Tracker – IHP'!$E:$E,36)) | F34: =IF(ISBLANK(INDEX('Milestone Tracker – IHP'!$F:$F,36)),"",INDEX('Milestone Tracker – IHP'!$F:$F,36)) | G34: =IF(ISBLANK(INDEX('Milestone Tracker – IHP'!#REF!,36)),"",INDEX('Milestone Tracker – IHP'!#REF!,36)) -> #REF! | H34: =IF(ISBLANK(INDEX('Milestone Tracker – IHP'!$G:$G,36)),"",INDEX('Milestone Tracker – IHP'!$G:$G,36)) | I34: =IF(ISBLANK(INDEX('Milestone Tracker – IHP'!$H:$H,36)),"",INDEX('Milestone Tracker – IHP'!$H:$H,36)) | J34: =IF(ISBLANK(INDEX('Milestone Tracker – IHP'!#REF!,36)),"",INDEX('Milestone Tracker – IHP'!#REF!,36)) -> #REF! | K34: =IF(LEFT($E34,9)="Milestone",1,0) -> 0 | L34: =L33+K34 -> 0
A35: 37 | B35: =IF(ISBLANK(INDEX('Milestone Tracker – IHP'!$B:$B,37)),B34,INDEX('Milestone Tracker – IHP'!$B:$B,37)) -> 0 | C35: =IF(ISBLANK(INDEX('Milestone Tracker – IHP'!$C:$C,37)),C34,INDEX('Milestone Tracker – IHP'!$C:$C,37)) -> 0 | D35: =IF(ISBLANK(INDEX('Milestone Tracker – IHP'!$D:$D,37)),D34,INDEX('Milestone Tracker – IHP'!$D:$D,37)) -> 0 | E35: =IF(ISBLANK(INDEX('Milestone Tracker – IHP'!$E:$E,37)),"",INDEX('Milestone Tracker – IHP'!$E:$E,37)) | F35: =IF(ISBLANK(INDEX('Milestone Tracker – IHP'!$F:$F,37)),"",INDEX('Milestone Tracker – IHP'!$F:$F,37)) | G35: =IF(ISBLANK(INDEX('Milestone Tracker – IHP'!#REF!,37)),"",INDEX('Milestone Tracker – IHP'!#REF!,37)) -> #REF! | H35: =IF(ISBLANK(INDEX('Milestone Tracker – IHP'!$G:$G,37)),"",INDEX('Milestone Tracker – IHP'!$G:$G,37)) | I35: =IF(ISBLANK(INDEX('Milestone Tracker – IHP'!$H:$H,37)),"",INDEX('Milestone Tracker – IHP'!$H:$H,37)) | J35: =IF(ISBLANK(INDEX('Milestone Tracker – IHP'!#REF!,37)),"",INDEX('Milestone Tracker – IHP'!#REF!,37)) -> #REF! | K35: =IF(LEFT($E35,9)="Milestone",1,0) -> 0 | L35: =L34+K35 -> 0
A36: 38 | B36: =IF(ISBLANK(INDEX('Milestone Tracker – IHP'!$B:$B,38)),B35,INDEX('Milestone Tracker – IHP'!$B:$B,38)) -> 0 | C36: =IF(ISBLANK(INDEX('Milestone Tracker – IHP'!$C:$C,38)),C35,INDEX('Milestone Tracker – IHP'!$C:$C,38)) -> 0 | D36: =IF(ISBLANK(INDEX('Milestone Tracker – IHP'!$D:$D,38)),D35,INDEX('Milestone Tracker – IHP'!$D:$D,38)) -> 0 | E36: =IF(ISBLANK(INDEX('Milestone Tracker – IHP'!$E:$E,38)),"",INDEX('Milestone Tracker – IHP'!$E:$E,38)) | F36: =IF(ISBLANK(INDEX('Milestone Tracker – IHP'!$F:$F,38)),"",INDEX('Milestone Tracker – IHP'!$F:$F,38)) | G36: =IF(ISBLANK(INDEX('Milestone Tracker – IHP'!#REF!,38)),"",INDEX('Milestone Tracker – IHP'!#REF!,38)) -> #REF! | H36: =IF(ISBLANK(INDEX('Milestone Tracker – IHP'!$G:$G,38)),"",INDEX('Milestone Tracker – IHP'!$G:$G,38)) | I36: =IF(ISBLANK(INDEX('Milestone Tracker – IHP'!$H:$H,38)),"",INDEX('Milestone Tracker – IHP'!$H:$H,38)) | J36: =IF(ISBLANK(INDEX('Milestone Tracker – IHP'!#REF!,38)),"",INDEX('Milestone Tracker – IHP'!#REF!,38)) -> #REF! | K36: =IF(LEFT($E36,9)="Milestone",1,0) -> 0 | L36: =L35+K36 -> 0
A37: 39 | B37: =IF(ISBLANK(INDEX('Milestone Tracker – IHP'!$B:$B,39)),B36,INDEX('Milestone Tracker – IHP'!$B:$B,39)) -> 0 | C37: =IF(ISBLANK(INDEX('Milestone Tracker – IHP'!$C:$C,39)),C36,INDEX('Milestone Tracker – IHP'!$C:$C,39)) -> 0 | D37: =IF(ISBLANK(INDEX('Milestone Tracker – IHP'!$D:$D,39)),D36,INDEX('Milestone Tracker – IHP'!$D:$D,39)) -> 0 | E37: =IF(ISBLANK(INDEX('Milestone Tracker – IHP'!$E:$E,39)),"",INDEX('Milestone Tracker – IHP'!$E:$E,39)) | F37: =IF(ISBLANK(INDEX('Milestone Tracker – IHP'!$F:$F,39)),"",INDEX('Milestone Tracker – IHP'!$F:$F,39)) | G37: =IF(ISBLANK(INDEX('Milestone Tracker – IHP'!#REF!,39)),"",INDEX('Milestone Tracker – IHP'!#REF!,39)) -> #REF! | H37: =IF(ISBLANK(INDEX('Milestone Tracker – IHP'!$G:$G,39)),"",INDEX('Milestone Tracker – IHP'!$G:$G,39)) | I37: =IF(ISBLANK(INDEX('Milestone Tracker – IHP'!$H:$H,39)),"",INDEX('Milestone Tracker – IHP'!$H:$H,39)) | J37: =IF(ISBLANK(INDEX('Milestone Tracker – IHP'!#REF!,39)),"",INDEX('Milestone Tracker – IHP'!#REF!,39)) -> #REF! | K37: =IF(LEFT($E37,9)="Milestone",1,0) -> 0 | L37: =L36+K37 -> 0
A38: 40 | B38: =IF(ISBLANK(INDEX('Milestone Tracker – IHP'!$B:$B,40)),B37,INDEX('Milestone Tracker – IHP'!$B:$B,40)) -> 0 | C38: =IF(ISBLANK(INDEX('Milestone Tracker – IHP'!$C:$C,40)),C37,INDEX('Milestone Tracker – IHP'!$C:$C,40)) -> 0 | D38: =IF(ISBLANK(INDEX('Milestone Tracker – IHP'!$D:$D,40)),D37,INDEX('Milestone Tracker – IHP'!$D:$D,40)) -> 0 | E38: =IF(ISBLANK(INDEX('Milestone Tracker – IHP'!$E:$E,40)),"",INDEX('Milestone Tracker – IHP'!$E:$E,40)) | F38: =IF(ISBLANK(INDEX('Milestone Tracker – IHP'!$F:$F,40)),"",INDEX('Milestone Tracker – IHP'!$F:$F,40)) | G38: =IF(ISBLANK(INDEX('Milestone Tracker – IHP'!#REF!,40)),"",INDEX('Milestone Tracker – IHP'!#REF!,40)) -> #REF! | H38: =IF(ISBLANK(INDEX('Milestone Tracker – IHP'!$G:$G,40)),"",INDEX('Milestone Tracker – IHP'!$G:$G,40)) | I38: =IF(ISBLANK(INDEX('Milestone Tracker – IHP'!$H:$H,40)),"",INDEX('Milestone Tracker – IHP'!$H:$H,40)) | J38: =IF(ISBLANK(INDEX('Milestone Tracker – IHP'!#REF!,40)),"",INDEX('Milestone Tracker – IHP'!#REF!,40)) -> #REF! | K38: =IF(LEFT($E38,9)="Milestone",1,0) -> 0 | L38: =L37+K38 -> 0
A39: 41 | B39: =IF(ISBLANK(INDEX('Milestone Tracker – IHP'!$B:$B,41)),B38,INDEX('Milestone Tracker – IHP'!$B:$B,41)) -> 0 | C39: =IF(ISBLANK(INDEX('Milestone Tracker – IHP'!$C:$C,41)),C38,INDEX('Milestone Tracker – IHP'!$C:$C,41)) -> 0 | D39: =IF(ISBLANK(INDEX('Milestone Tracker – IHP'!$D:$D,41)),D38,INDEX('Milestone Tracker – IHP'!$D:$D,41)) -> 0 | E39: =IF(ISBLANK(INDEX('Milestone Tracker – IHP'!$E:$E,41)),"",INDEX('Milestone Tracker – IHP'!$E:$E,41)) | F39: =IF(ISBLANK(INDEX('Milestone Tracker – IHP'!$F:$F,41)),"",INDEX('Milestone Tracker – IHP'!$F:$F,41)) | G39: =IF(ISBLANK(INDEX('Milestone Tracker – IHP'!#REF!,41)),"",INDEX('Milestone Tracker – IHP'!#REF!,41)) -> #REF! | H39: =IF(ISBLANK(INDEX('Milestone Tracker – IHP'!$G:$G,41)),"",INDEX('Milestone Tracker – IHP'!$G:$G,41)) | I39: =IF(ISBLANK(INDEX('Milestone Tracker – IHP'!$H:$H,41)),"",INDEX('Milestone Tracker – IHP'!$H:$H,41)) | J39: =IF(ISBLANK(INDEX('Milestone Tracker – IHP'!#REF!,41)),"",INDEX('Milestone Tracker – IHP'!#REF!,41)) -> #REF! | K39: =IF(LEFT($E39,9)="Milestone",1,0) -> 0 | L39: =L38+K39 -> 0
A40: 42 | B40: =IF(ISBLANK(INDEX('Milestone Tracker – IHP'!$B:$B,42)),B39,INDEX('Milestone Tracker – IHP'!$B:$B,42)) -> 0 | C40: =IF(ISBLANK(INDEX('Milestone Tracker – IHP'!$C:$C,42)),C39,INDEX('Milestone Tracker – IHP'!$C:$C,42)) -> 0 | D40: =IF(ISBLANK(INDEX('Milestone Tracker – IHP'!$D:$D,42)),D39,INDEX('Milestone Tracker – IHP'!$D:$D,42)) -> 0 | E40: =IF(ISBLANK(INDEX('Milestone Tracker – IHP'!$E:$E,42)),"",INDEX('Milestone Tracker – IHP'!$E:$E,42)) | F40: =IF(ISBLANK(INDEX('Milestone Tracker – IHP'!$F:$F,42)),"",INDEX('Milestone Tracker – IHP'!$F:$F,42)) | G40: =IF(ISBLANK(INDEX('Milestone Tracker – IHP'!#REF!,42)),"",INDEX('Milestone Tracker – IHP'!#REF!,42)) -> #REF! | H40: =IF(ISBLANK(INDEX('Milestone Tracker – IHP'!$G:$G,42)),"",INDEX('Milestone Tracker – IHP'!$G:$G,42)) | I40: =IF(ISBLANK(INDEX('Milestone Tracker – IHP'!$H:$H,42)),"",INDEX('Milestone Tracker – IHP'!$H:$H,42)) | J40: =IF(ISBLANK(INDEX('Milestone Tracker – IHP'!#REF!,42)),"",INDEX('Milestone Tracker – IHP'!#REF!,42)) -> #REF! | K40: =IF(LEFT($E40,9)="Milestone",1,0) -> 0 | L40: =L39+K40 -> 0
...
